<mujoco model="demo">
	<extension>
		<plugin plugin="mujoco.elasticity.solid" />
	</extension>
	<include file="scene.xml" />
	<worldbody>
		<body name="v1" pos="0.128 0.20800000000000002 0.10500000000000001">
			<inertial pos="0 0 0" mass="0.01" diaginertia="1.66667e-05 1.66667e-05 1.66667e-05" />
			<joint name="v1_j1" pos="0 0 0" axis="1 0 0" type="slide" />
			<joint name="v1_j2" pos="0 0 0" axis="0 1 0" type="slide" />
			<joint name="v1_j3" pos="0 0 0" axis="0 0 1" type="slide" />
		</body>
		<body name="v2" pos="0.202 0.20800000000000002 0.10500000000000001">
			<inertial pos="0 0 0" mass="0.01" diaginertia="1.66667e-05 1.66667e-05 1.66667e-05" />
			<joint name="v2_j1" pos="0 0 0" axis="1 0 0" type="slide" />
			<joint name="v2_j2" pos="0 0 0" axis="0 1 0" type="slide" />
			<joint name="v2_j3" pos="0 0 0" axis="0 0 1" type="slide" />
		</body>
		<body name="v3" pos="0.372 0.20800000000000002 0.10500000000000001">
			<inertial pos="0 0 0" mass="0.01" diaginertia="1.66667e-05 1.66667e-05 1.66667e-05" />
			<joint name="v3_j1" pos="0 0 0" axis="1 0 0" type="slide" />
			<joint name="v3_j2" pos="0 0 0" axis="0 1 0" type="slide" />
			<joint name="v3_j3" pos="0 0 0" axis="0 0 1" type="slide" />
		</body>
		<body name="v4" pos="0.5429999999999999 0.20800000000000002 0.10500000000000001">
			<inertial pos="0 0 0" mass="0.01" diaginertia="1.66667e-05 1.66667e-05 1.66667e-05" />
			<joint name="v4_j1" pos="0 0 0" axis="1 0 0" type="slide" />
			<joint name="v4_j2" pos="0 0 0" axis="0 1 0" type="slide" />
			<joint name="v4_j3" pos="0 0 0" axis="0 0 1" type="slide" />
		</body>
		<body name="v5" pos="0.605 0.20800000000000002 0.10500000000000001">
			<inertial pos="0 0 0" mass="0.01" diaginertia="1.66667e-05 1.66667e-05 1.66667e-05" />
			<joint name="v5_j1" pos="0 0 0" axis="1 0 0" type="slide" />
			<joint name="v5_j2" pos="0 0 0" axis="0 1 0" type="slide" />
			<joint name="v5_j3" pos="0 0 0" axis="0 0 1" type="slide" />
		</body>
		<body name="v6" pos="0.605 0.31 0.10500000000000001">
			<inertial pos="0 0 0" mass="0.01" diaginertia="1.66667e-05 1.66667e-05 1.66667e-05" />
			<joint name="v6_j1" pos="0 0 0" axis="1 0 0" type="slide" />
			<joint name="v6_j2" pos="0 0 0" axis="0 1 0" type="slide" />
			<joint name="v6_j3" pos="0 0 0" axis="0 0 1" type="slide" />
		</body>
		<body name="v7" pos="0.5429999999999999 0.31 0.10500000000000001">
			<inertial pos="0 0 0" mass="0.01" diaginertia="1.66667e-05 1.66667e-05 1.66667e-05" />
			<joint name="v7_j1" pos="0 0 0" axis="1 0 0" type="slide" />
			<joint name="v7_j2" pos="0 0 0" axis="0 1 0" type="slide" />
			<joint name="v7_j3" pos="0 0 0" axis="0 0 1" type="slide" />
		</body>
		<body name="v8" pos="0.372 0.31 0.10500000000000001">
			<inertial pos="0 0 0" mass="0.01" diaginertia="1.66667e-05 1.66667e-05 1.66667e-05" />
			<joint name="v8_j1" pos="0 0 0" axis="1 0 0" type="slide" />
			<joint name="v8_j2" pos="0 0 0" axis="0 1 0" type="slide" />
			<joint name="v8_j3" pos="0 0 0" axis="0 0 1" type="slide" />
		</body>
		<body name="v9" pos="0.202 0.31 0.10500000000000001">
			<inertial pos="0 0 0" mass="0.01" diaginertia="1.66667e-05 1.66667e-05 1.66667e-05" />
			<joint name="v9_j1" pos="0 0 0" axis="1 0 0" type="slide" />
			<joint name="v9_j2" pos="0 0 0" axis="0 1 0" type="slide" />
			<joint name="v9_j3" pos="0 0 0" axis="0 0 1" type="slide" />
		</body>
		<body name="v10" pos="0.128 0.31 0.10500000000000001">
			<inertial pos="0 0 0" mass="0.01" diaginertia="1.66667e-05 1.66667e-05 1.66667e-05" />
			<joint name="v10_j1" pos="0 0 0" axis="1 0 0" type="slide" />
			<joint name="v10_j2" pos="0 0 0" axis="0 1 0" type="slide" />
			<joint name="v10_j3" pos="0 0 0" axis="0 0 1" type="slide" />
		</body>
	</worldbody>
	<deformable>
		<flex name="body1" dim="2" body="v2 v1 v10 v9" vertex="0 0 0 0 0 0 0 0 0 0 0 0"
			element="2 1 0 0 3 2" rgba="0 0 1 0.9" />
		<flex name="body2" dim="2" body="v2 v3 v8 v9" vertex="0 0 0 0 0 0 0 0 0 0 0 0"
			element="3 0 1 1 2 3" rgba="0 0 1 0.9" />
		<flex name="body3" dim="2" body="v3 v4 v7 v8" vertex="0 0 0 0 0 0 0 0 0 0 0 0"
			element="3 0 1 1 2 3" rgba="0 0 1 0.9" />
		<flex name="body4" dim="2" body="v4 v5 v6 v7" vertex="0 0 0 0 0 0 0 0 0 0 0 0"
			element="3 0 1 1 2 3" rgba="0 0 1 0.9" />
	</deformable>
	<equality>
		<flex flex="body1" />
		<flex flex="body2" />
		<flex flex="body3" />
		<flex flex="body4" />
		<joint joint1="v3_j1" joint2="v8_j1" polycoef="0 1 0 0 0" />
		<joint joint1="v3_j2" joint2="v8_j2" polycoef="0 1 0 0 0" />
		<joint joint1="v3_j3" joint2="v8_j3" polycoef="0 1 0 0 0" />
		<joint joint1="v1_j1" joint2="v10_j1" polycoef="0 1 0 0 0" />
		<joint joint1="v1_j2" joint2="v10_j2" polycoef="0 1 0 0 0" />
		<joint joint1="v1_j3" joint2="v10_j3" polycoef="0 1 0 0 0" />
		<joint joint1="v7_j1" joint2="v4_j1" polycoef="0 1 0 0 0" />
		<joint joint1="v7_j2" joint2="v4_j2" polycoef="0 1 0 0 0" />
		<joint joint1="v7_j3" joint2="v4_j3" polycoef="0 1 0 0 0" />
		<joint joint1="v2_j1" joint2="v9_j1" polycoef="0 1 0 0 0" />
		<joint joint1="v2_j2" joint2="v9_j2" polycoef="0 1 0 0 0" />
		<joint joint1="v2_j3" joint2="v9_j3" polycoef="0 1 0 0 0" />
	</equality>
	<actuator>
		<position name="v8_actz" joint="v8_j3" dampratio="0.5" ctrlrange="-0.05 0.45" />
		<position name="v2_actz" joint="v2_j3" dampratio="0.5" ctrlrange="-0.05 0.45" />
		<position name="v1_actz" joint="v1_j3" dampratio="0.5" ctrlrange="-0.05 0.45" />
		<position name="v7_actz" joint="v7_j3" dampratio="0.5" ctrlrange="-0.05 0.45" />
		<position name="v5_actz" joint="v5_j3" dampratio="0.5" ctrlrange="-0.05 0.45" />
	</actuator>
</mujoco>