<mujoco model="demo">
	<extension>
		<plugin plugin="mujoco.elasticity.solid" />
	</extension>
	<include file="scene.xml" />
	<worldbody>
		<body name="v1" pos="2.1 2.09 1.005">
			<inertial pos="0 0 0" mass="0.01" diaginertia="1.66667e-05 1.66667e-05 1.66667e-05" />
			<joint name="v1_j1" pos="0 0 0" axis="1 0 0" type="slide" />
			<joint name="v1_j2" pos="0 0 0" axis="0 1 0" type="slide" />
			<joint name="v1_j3" pos="0 0 0" axis="0 0 1" type="slide" />
		</body>
		<body name="v2" pos="3.59 2.09 1.005">
			<inertial pos="0 0 0" mass="0.01" diaginertia="1.66667e-05 1.66667e-05 1.66667e-05" />
		</body>
		<body name="v3" pos="5.3 2.09 1.005">
			<inertial pos="0 0 0" mass="0.01" diaginertia="1.66667e-05 1.66667e-05 1.66667e-05" />
			<joint name="v3_j1" pos="0 0 0" axis="1 0 0" type="slide" />
			<joint name="v3_j2" pos="0 0 0" axis="0 1 0" type="slide" />
			<joint name="v3_j3" pos="0 0 0" axis="0 0 1" type="slide" />
		</body>
		<body name="v4" pos="5.3 3.45 1.005">
			<inertial pos="0 0 0" mass="0.01" diaginertia="1.66667e-05 1.66667e-05 1.66667e-05" />
			<joint name="v4_j1" pos="0 0 0" axis="1 0 0" type="slide" />
			<joint name="v4_j2" pos="0 0 0" axis="0 1 0" type="slide" />
			<joint name="v4_j3" pos="0 0 0" axis="0 0 1" type="slide" />
		</body>
		<body name="v5" pos="3.59 3.45 1.005">
			<inertial pos="0 0 0" mass="0.01" diaginertia="1.66667e-05 1.66667e-05 1.66667e-05" />
		</body>
		<body name="v6" pos="2.1 3.45 1.005">
			<inertial pos="0 0 0" mass="0.01" diaginertia="1.66667e-05 1.66667e-05 1.66667e-05" />
			<joint name="v6_j1" pos="0 0 0" axis="1 0 0" type="slide" />
			<joint name="v6_j2" pos="0 0 0" axis="0 1 0" type="slide" />
			<joint name="v6_j3" pos="0 0 0" axis="0 0 1" type="slide" />
		</body>
	</worldbody>
	<deformable>
		<flex name="body1" dim="2" body="v2 v1 v6 v5" vertex="0 0 0 0 0 0 0 0 0 0 0 0" element="2 1 0 0 3 2" rgba="0 0 1 0.9" />
		<flex name="body2" dim="2" body="v2 v3 v4 v5" vertex="0 0 0 0 0 0 0 0 0 0 0 0" element="3 0 1 1 2 3" rgba="0 0 1 0.9" />
	</deformable>
	<equality>
		<flex flex="body1" />
		<flex flex="body2" />
	</equality>
</mujoco>