<mujoco model="demo">
	<extension>
		<plugin plugin="mujoco.elasticity.solid" />
	</extension>
	<include file="scene.xml" />
	<worldbody>
		<body name="v1" pos="0.131 0.194 1.005">
			<inertial pos="0 0 0" mass="0.01" diaginertia="1.66667e-05 1.66667e-05 1.66667e-05" />
		</body>
		<body name="v2" pos="0.248 0.194 1.005">
			<inertial pos="0 0 0" mass="0.01" diaginertia="1.66667e-05 1.66667e-05 1.66667e-05" />
		</body>
		<body name="v3" pos="0.361 0.194 1.005">
			<inertial pos="0 0 0" mass="0.01" diaginertia="1.66667e-05 1.66667e-05 1.66667e-05" />
		</body>
		<body name="v4" pos="0.483 0.194 1.005">
			<inertial pos="0 0 0" mass="0.01" diaginertia="1.66667e-05 1.66667e-05 1.66667e-05" />
		</body>
		<body name="v5" pos="0.611 0.194 1.005">
			<inertial pos="0 0 0" mass="0.01" diaginertia="1.66667e-05 1.66667e-05 1.66667e-05" />
		</body>
		<body name="v6" pos="0.42 0.194 1.005">
			<inertial pos="0 0 0" mass="0.01" diaginertia="1.66667e-05 1.66667e-05 1.66667e-05" />
			<joint name="v6_j1" pos="0 0 0" axis="1 0 0" type="slide" />
			<joint name="v6_j3" pos="0 0 0" axis="0 0 1" type="slide" />
		</body>
		<body name="v7" pos="0.611 0.317 1.005">
			<inertial pos="0 0 0" mass="0.01" diaginertia="1.66667e-05 1.66667e-05 1.66667e-05" />
		</body>
		<body name="v8" pos="0.483 0.317 1.005">
			<inertial pos="0 0 0" mass="0.01" diaginertia="1.66667e-05 1.66667e-05 1.66667e-05" />
		</body>
		<body name="v9" pos="0.42 0.317 1.005">
			<inertial pos="0 0 0" mass="0.01" diaginertia="1.66667e-05 1.66667e-05 1.66667e-05" />
			<joint name="v9_j1" pos="0 0 0" axis="1 0 0" type="slide" />
			<joint name="v9_j3" pos="0 0 0" axis="0 0 1" type="slide" />
		</body>
		<body name="v10" pos="0.361 0.317 1.005">
			<inertial pos="0 0 0" mass="0.01" diaginertia="1.66667e-05 1.66667e-05 1.66667e-05" />
		</body>
		<body name="v11" pos="0.248 0.317 1.005">
			<inertial pos="0 0 0" mass="0.01" diaginertia="1.66667e-05 1.66667e-05 1.66667e-05" />
		</body>
		<body name="v12" pos="0.131 0.317 1.005">
			<inertial pos="0 0 0" mass="0.01" diaginertia="1.66667e-05 1.66667e-05 1.66667e-05" />
			<joint name="v12_j3" pos="0 0 0" axis="0 0 1" type="slide" />
		</body>
	</worldbody>
	<deformable>
		<flex name="body1" dim="2" body="v2 v1 v12 v11" vertex="0 0 0 0 0 0 0 0 0 0 0 0" element="2 1 0 0 3 2" rgba="0 0 1 0.9" />
		<flex name="body2" dim="2" body="v2 v3 v10 v11" vertex="0 0 0 0 0 0 0 0 0 0 0 0" element="3 0 1 1 2 3" rgba="0 0 1 0.9" />
		<flex name="body3" dim="2" body="v3 v6 v9 v10" vertex="0 0 0 0 0 0 0 0 0 0 0 0" element="3 0 1 1 2 3" rgba="0 0 1 0.9" />
		<flex name="body4" dim="2" body="v4 v6 v9 v8" vertex="0 0 0 0 0 0 0 0 0 0 0 0" element="2 1 0 0 3 2" rgba="0 0 1 0.9" />
		<flex name="body5" dim="2" body="v4 v5 v7 v8" vertex="0 0 0 0 0 0 0 0 0 0 0 0" element="3 0 1 1 2 3" rgba="0 0 1 0.9" />
	</deformable>
	<equality>
		<flex flex="body1" />
		<flex flex="body2" />
		<flex flex="body3" />
		<flex flex="body4" />
		<flex flex="body5" />
	</equality>
	<actuator />
</mujoco>