<mujoco model="demo">
	<extension>
		<plugin plugin="mujoco.elasticity.solid" />
	</extension>
	<include file="scene.xml" />
	<worldbody>
		<body name="v1" pos="0.12 0.19 0.10500000000000001">
			<inertial pos="0 0 0" mass="0.01" diaginertia="1.66667e-05 1.66667e-05 1.66667e-05" />
			<joint name="v1_j3" pos="0 0 0" axis="0 0 1" type="slide" />
		</body>
		<body name="v2" pos="0.16799999999999998 0.19 0.10500000000000001">
			<inertial pos="0 0 0" mass="0.01" diaginertia="1.66667e-05 1.66667e-05 1.66667e-05" />
			<joint name="v2_j1" pos="0 0 0" axis="1 0 0" type="slide" />
			<joint name="v2_j2" pos="0 0 0" axis="0 1 0" type="slide" />
			<joint name="v2_j3" pos="0 0 0" axis="0 0 1" type="slide" />
		</body>
		<body name="v3" pos="0.215 0.19 0.10500000000000001">
			<inertial pos="0 0 0" mass="0.01" diaginertia="1.66667e-05 1.66667e-05 1.66667e-05" />
		</body>
		<body name="v4" pos="0.317 0.19 0.10500000000000001">
			<inertial pos="0 0 0" mass="0.01" diaginertia="1.66667e-05 1.66667e-05 1.66667e-05" />
		</body>
		<body name="v5" pos="0.364 0.19 0.10500000000000001">
			<inertial pos="0 0 0" mass="0.01" diaginertia="1.66667e-05 1.66667e-05 1.66667e-05" />
			<joint name="v5_j1" pos="0 0 0" axis="1 0 0" type="slide" />
			<joint name="v5_j2" pos="0 0 0" axis="0 1 0" type="slide" />
			<joint name="v5_j3" pos="0 0 0" axis="0 0 1" type="slide" />
		</body>
		<body name="v6" pos="0.42300000000000004 0.19 0.10500000000000001">
			<inertial pos="0 0 0" mass="0.01" diaginertia="1.66667e-05 1.66667e-05 1.66667e-05" />
			<joint name="v6_j3" pos="0 0 0" axis="0 0 1" type="slide" />
		</body>
		<body name="v7" pos="0.42300000000000004 0.311 0.10500000000000001">
			<inertial pos="0 0 0" mass="0.01" diaginertia="1.66667e-05 1.66667e-05 1.66667e-05" />
			<joint name="v7_j3" pos="0 0 0" axis="0 0 1" type="slide" />
		</body>
		<body name="v8" pos="0.364 0.311 0.10500000000000001">
			<inertial pos="0 0 0" mass="0.01" diaginertia="1.66667e-05 1.66667e-05 1.66667e-05" />
			<joint name="v8_j1" pos="0 0 0" axis="1 0 0" type="slide" />
			<joint name="v8_j2" pos="0 0 0" axis="0 1 0" type="slide" />
			<joint name="v8_j3" pos="0 0 0" axis="0 0 1" type="slide" />
		</body>
		<body name="v9" pos="0.317 0.311 0.10500000000000001">
			<inertial pos="0 0 0" mass="0.01" diaginertia="1.66667e-05 1.66667e-05 1.66667e-05" />
		</body>
		<body name="v10" pos="0.215 0.311 0.10500000000000001">
			<inertial pos="0 0 0" mass="0.01" diaginertia="1.66667e-05 1.66667e-05 1.66667e-05" />
		</body>
		<body name="v11" pos="0.16799999999999998 0.311 0.10500000000000001">
			<inertial pos="0 0 0" mass="0.01" diaginertia="1.66667e-05 1.66667e-05 1.66667e-05" />
			<joint name="v11_j1" pos="0 0 0" axis="1 0 0" type="slide" />
			<joint name="v11_j2" pos="0 0 0" axis="0 1 0" type="slide" />
			<joint name="v11_j3" pos="0 0 0" axis="0 0 1" type="slide" />
		</body>
		<body name="v12" pos="0.12 0.311 0.10500000000000001">
			<inertial pos="0 0 0" mass="0.01" diaginertia="1.66667e-05 1.66667e-05 1.66667e-05" />
			<joint name="v12_j3" pos="0 0 0" axis="0 0 1" type="slide" />
		</body>
		<body name="v13" pos="0.542 0.19 0.10500000000000001">
			<inertial pos="0 0 0" mass="0.01" diaginertia="1.66667e-05 1.66667e-05 1.66667e-05" />
		</body>
		<body name="v14" pos="0.542 0.311 0.10500000000000001">
			<inertial pos="0 0 0" mass="0.01" diaginertia="1.66667e-05 1.66667e-05 1.66667e-05" />
		</body>
	</worldbody>
	<deformable>
		<flex name="body1" dim="2" body="v2 v1 v12 v11" vertex="0 0 0 0 0 0 0 0 0 0 0 0" element="2 1 0 0 3 2" rgba="0 0 1 0.9" />
		<flex name="body2" dim="2" body="v2 v3 v10 v11" vertex="0 0 0 0 0 0 0 0 0 0 0 0" element="3 0 1 1 2 3" rgba="0 0 1 0.9" />
		<flex name="body3" dim="2" body="v3 v4 v9 v10" vertex="0 0 0 0 0 0 0 0 0 0 0 0" element="3 0 1 1 2 3" rgba="0 0 1 0.9" />
		<flex name="body4" dim="2" body="v4 v5 v8 v9" vertex="0 0 0 0 0 0 0 0 0 0 0 0" element="3 0 1 1 2 3" rgba="0 0 1 0.9" />
		<flex name="body5" dim="2" body="v5 v6 v7 v8" vertex="0 0 0 0 0 0 0 0 0 0 0 0" element="3 0 1 1 2 3" rgba="0 0 1 0.9" />
		<flex name="body6" dim="2" body="v6 v13 v14 v7" vertex="0 0 0 0 0 0 0 0 0 0 0 0" element="3 0 1 1 2 3" rgba="0 0 1 0.9" />
	</deformable>
	<equality>
		<flex flex="body1" />
		<flex flex="body2" />
		<flex flex="body3" />
		<flex flex="body4" />
		<flex flex="body5" />
		<flex flex="body6" />
	</equality>
	<actuator />
</mujoco>