<mujoco model="demo">
	<extension>
		<plugin plugin="mujoco.elasticity.solid" />
	</extension>
	<include file="scene.xml" />
	<worldbody>
		<body name="v1" pos="0.292 0.20400000000000001 0.10500000000000001">
			<inertial pos="0 0 0" mass="0.01" diaginertia="1.66667e-05 1.66667e-05 1.66667e-05" />
		</body>
		<body name="v2" pos="0.41600000000000004 0.20400000000000001 0.10500000000000001">
			<inertial pos="0 0 0" mass="0.01" diaginertia="1.66667e-05 1.66667e-05 1.66667e-05" />
		</body>
		<body name="v3" pos="0.41600000000000004 0.309 0.10500000000000001">
			<inertial pos="0 0 0" mass="0.01" diaginertia="1.66667e-05 1.66667e-05 1.66667e-05" />
		</body>
		<body name="v4" pos="0.292 0.309 0.10500000000000001">
			<inertial pos="0 0 0" mass="0.01" diaginertia="1.66667e-05 1.66667e-05 1.66667e-05" />
		</body>
		<body name="v5" pos="0.16399999999999998 0.20400000000000001 0.10500000000000001">
			<inertial pos="0 0 0" mass="0.01" diaginertia="1.66667e-05 1.66667e-05 1.66667e-05" />
			<joint name="v5_j1" pos="0 0 0" axis="1 0 0" type="slide" />
			<joint name="v5_j2" pos="0 0 0" axis="0 1 0" type="slide" />
			<joint name="v5_j3" pos="0 0 0" axis="0 0 1" type="slide" />
		</body>
		<body name="v6" pos="0.16399999999999998 0.309 0.10500000000000001">
			<inertial pos="0 0 0" mass="0.01" diaginertia="1.66667e-05 1.66667e-05 1.66667e-05" />
			<joint name="v6_j1" pos="0 0 0" axis="1 0 0" type="slide" />
			<joint name="v6_j2" pos="0 0 0" axis="0 1 0" type="slide" />
			<joint name="v6_j3" pos="0 0 0" axis="0 0 1" type="slide" />
		</body>
		<body name="v7" pos="0.292 0.41600000000000004 0.10500000000000001">
			<inertial pos="0 0 0" mass="0.01" diaginertia="1.66667e-05 1.66667e-05 1.66667e-05" />
			<joint name="v7_j1" pos="0 0 0" axis="1 0 0" type="slide" />
			<joint name="v7_j2" pos="0 0 0" axis="0 1 0" type="slide" />
			<joint name="v7_j3" pos="0 0 0" axis="0 0 1" type="slide" />
		</body>
		<body name="v8" pos="0.41600000000000004 0.41600000000000004 0.10500000000000001">
			<inertial pos="0 0 0" mass="0.01" diaginertia="1.66667e-05 1.66667e-05 1.66667e-05" />
			<joint name="v8_j1" pos="0 0 0" axis="1 0 0" type="slide" />
			<joint name="v8_j2" pos="0 0 0" axis="0 1 0" type="slide" />
			<joint name="v8_j3" pos="0 0 0" axis="0 0 1" type="slide" />
		</body>
		<body name="v9" pos="0.5549999999999999 0.309 0.10500000000000001">
			<inertial pos="0 0 0" mass="0.01" diaginertia="1.66667e-05 1.66667e-05 1.66667e-05" />
			<joint name="v9_j1" pos="0 0 0" axis="1 0 0" type="slide" />
			<joint name="v9_j2" pos="0 0 0" axis="0 1 0" type="slide" />
			<joint name="v9_j3" pos="0 0 0" axis="0 0 1" type="slide" />
		</body>
		<body name="v10" pos="0.5549999999999999 0.20400000000000001 0.10500000000000001">
			<inertial pos="0 0 0" mass="0.01" diaginertia="1.66667e-05 1.66667e-05 1.66667e-05" />
			<joint name="v10_j1" pos="0 0 0" axis="1 0 0" type="slide" />
			<joint name="v10_j2" pos="0 0 0" axis="0 1 0" type="slide" />
			<joint name="v10_j3" pos="0 0 0" axis="0 0 1" type="slide" />
		</body>
		<body name="v11" pos="0.41600000000000004 0.059 0.10500000000000001">
			<inertial pos="0 0 0" mass="0.01" diaginertia="1.66667e-05 1.66667e-05 1.66667e-05" />
			<joint name="v11_j1" pos="0 0 0" axis="1 0 0" type="slide" />
			<joint name="v11_j2" pos="0 0 0" axis="0 1 0" type="slide" />
			<joint name="v11_j3" pos="0 0 0" axis="0 0 1" type="slide" />
		</body>
		<body name="v12" pos="0.292 0.059 0.10500000000000001">
			<inertial pos="0 0 0" mass="0.01" diaginertia="1.66667e-05 1.66667e-05 1.66667e-05" />
			<joint name="v12_j1" pos="0 0 0" axis="1 0 0" type="slide" />
			<joint name="v12_j2" pos="0 0 0" axis="0 1 0" type="slide" />
			<joint name="v12_j3" pos="0 0 0" axis="0 0 1" type="slide" />
		</body>
	</worldbody>
	<deformable>
		<flex name="body1" dim="2" body="v1 v4 v3 v2" vertex="0 0 0 0 0 0 0 0 0 0 0 0" element="1 0 3 3 2 1" rgba="0 0 1 0.9" />
		<flex name="body2" dim="2" body="v1 v11 v2" vertex="0 0 0 0 0 0 0 0 0" element="1 2 0" rgba="0 0 1 0.9" />
		<flex name="body3" dim="2" body="v1 v12 v11" vertex="0 0 0 0 0 0 0 0 0" element="1 2 0" rgba="0 0 1 0.9" />
		<flex name="body4" dim="2" body="v1 v5 v4" vertex="0 0 0 0 0 0 0 0 0" element="1 0 2" rgba="0 0 1 0.9" />
		<flex name="body5" dim="2" body="v4 v6 v5" vertex="0 0 0 0 0 0 0 0 0" element="2 0 1" rgba="0 0 1 0.9" />
		<flex name="body6" dim="2" body="v3 v7 v4" vertex="0 0 0 0 0 0 0 0 0" element="2 0 1" rgba="0 0 1 0.9" />
		<flex name="body7" dim="2" body="v3 v8 v7" vertex="0 0 0 0 0 0 0 0 0" element="0 1 2" rgba="0 0 1 0.9" />
		<flex name="body8" dim="2" body="v2 v9 v3" vertex="0 0 0 0 0 0 0 0 0" element="0 1 2" rgba="0 0 1 0.9" />
		<flex name="body9" dim="2" body="v2 v10 v9" vertex="0 0 0 0 0 0 0 0 0" element="0 1 2" rgba="0 0 1 0.9" />
	</deformable>
	<equality>
		<flex flex="body1" />
		<flex flex="body2" />
		<flex flex="body3" />
		<flex flex="body4" />
		<flex flex="body5" />
		<flex flex="body6" />
		<flex flex="body7" />
		<flex flex="body8" />
		<flex flex="body9" />
	</equality>
	<actuator />
</mujoco>